2022-02-16 20:12:16,348 INFO: Microblog startup [in C:\Users\Dell\Documents\finance\app\__init__.py:78]
2022-02-16 20:13:52,405 ERROR: Exception on / [GET] [in c:\users\dell\appdata\local\programs\python\python38\lib\site-packages\flask\app.py:1454]
Traceback (most recent call last):
  File "c:\users\dell\appdata\local\programs\python\python38\lib\site-packages\flask\app.py", line 2070, in wsgi_app
    response = self.full_dispatch_request()
  File "c:\users\dell\appdata\local\programs\python\python38\lib\site-packages\flask\app.py", line 1515, in full_dispatch_request
    rv = self.handle_user_exception(e)
  File "c:\users\dell\appdata\local\programs\python\python38\lib\site-packages\flask\app.py", line 1511, in full_dispatch_request
    rv = self.preprocess_request()
  File "c:\users\dell\appdata\local\programs\python\python38\lib\site-packages\flask\app.py", line 1857, in preprocess_request
    rv = self.ensure_sync(func)()
  File "C:\Users\Dell\Documents\finance\app\main\routes.py", line 17, in before_request
    if current_user.is_authenticated:
  File "c:\users\dell\appdata\local\programs\python\python38\lib\site-packages\werkzeug\local.py", line 422, in __get__
    obj = instance._get_current_object()
  File "c:\users\dell\appdata\local\programs\python\python38\lib\site-packages\werkzeug\local.py", line 544, in _get_current_object
    return self.__local()  # type: ignore
  File "c:\users\dell\appdata\local\programs\python\python38\lib\site-packages\flask_login\utils.py", line 26, in <lambda>
    current_user = LocalProxy(lambda: _get_user())
  File "c:\users\dell\appdata\local\programs\python\python38\lib\site-packages\flask_login\utils.py", line 346, in _get_user
    current_app.login_manager._load_user()
  File "c:\users\dell\appdata\local\programs\python\python38\lib\site-packages\flask_login\login_manager.py", line 318, in _load_user
    user = self._user_callback(user_id)
  File "C:\Users\Dell\Documents\finance\app\models.py", line 99, in load_user
    return User.query.get(int(id))
  File "c:\users\dell\appdata\local\programs\python\python38\lib\site-packages\flask_sqlalchemy\__init__.py", line 550, in __get__
    mapper = orm.class_mapper(type)
  File "c:\users\dell\appdata\local\programs\python\python38\lib\site-packages\sqlalchemy\orm\base.py", line 436, in class_mapper
    mapper = _inspect_mapped_class(class_, configure=configure)
  File "c:\users\dell\appdata\local\programs\python\python38\lib\site-packages\sqlalchemy\orm\base.py", line 415, in _inspect_mapped_class
    mapper._check_configure()
  File "c:\users\dell\appdata\local\programs\python\python38\lib\site-packages\sqlalchemy\orm\mapper.py", line 1873, in _check_configure
    _configure_registries({self.registry}, cascade=True)
  File "c:\users\dell\appdata\local\programs\python\python38\lib\site-packages\sqlalchemy\orm\mapper.py", line 3384, in _configure_registries
    _do_configure_registries(registries, cascade)
  File "c:\users\dell\appdata\local\programs\python\python38\lib\site-packages\sqlalchemy\orm\mapper.py", line 3423, in _do_configure_registries
    mapper._post_configure_properties()
  File "c:\users\dell\appdata\local\programs\python\python38\lib\site-packages\sqlalchemy\orm\mapper.py", line 1890, in _post_configure_properties
    prop.init()
  File "c:\users\dell\appdata\local\programs\python\python38\lib\site-packages\sqlalchemy\orm\interfaces.py", line 222, in init
    self.do_init()
  File "c:\users\dell\appdata\local\programs\python\python38\lib\site-packages\sqlalchemy\orm\relationships.py", line 2142, in do_init
    self._generate_backref()
  File "c:\users\dell\appdata\local\programs\python\python38\lib\site-packages\sqlalchemy\orm\relationships.py", line 2422, in _generate_backref
    raise sa_exc.ArgumentError(
sqlalchemy.exc.ArgumentError: Error creating backref 'user_id' on relationship 'User.CurrentStock': property of that name exists on mapper 'mapped class CurrentStock->current_stock'
2022-02-16 20:13:52,989 ERROR: Exception on /favicon.ico [GET] [in c:\users\dell\appdata\local\programs\python\python38\lib\site-packages\flask\app.py:1454]
Traceback (most recent call last):
  File "c:\users\dell\appdata\local\programs\python\python38\lib\site-packages\flask\app.py", line 2070, in wsgi_app
    response = self.full_dispatch_request()
  File "c:\users\dell\appdata\local\programs\python\python38\lib\site-packages\flask\app.py", line 1515, in full_dispatch_request
    rv = self.handle_user_exception(e)
  File "c:\users\dell\appdata\local\programs\python\python38\lib\site-packages\flask\app.py", line 1511, in full_dispatch_request
    rv = self.preprocess_request()
  File "c:\users\dell\appdata\local\programs\python\python38\lib\site-packages\flask\app.py", line 1857, in preprocess_request
    rv = self.ensure_sync(func)()
  File "C:\Users\Dell\Documents\finance\app\main\routes.py", line 17, in before_request
    if current_user.is_authenticated:
  File "c:\users\dell\appdata\local\programs\python\python38\lib\site-packages\werkzeug\local.py", line 422, in __get__
    obj = instance._get_current_object()
  File "c:\users\dell\appdata\local\programs\python\python38\lib\site-packages\werkzeug\local.py", line 544, in _get_current_object
    return self.__local()  # type: ignore
  File "c:\users\dell\appdata\local\programs\python\python38\lib\site-packages\flask_login\utils.py", line 26, in <lambda>
    current_user = LocalProxy(lambda: _get_user())
  File "c:\users\dell\appdata\local\programs\python\python38\lib\site-packages\flask_login\utils.py", line 346, in _get_user
    current_app.login_manager._load_user()
  File "c:\users\dell\appdata\local\programs\python\python38\lib\site-packages\flask_login\login_manager.py", line 318, in _load_user
    user = self._user_callback(user_id)
  File "C:\Users\Dell\Documents\finance\app\models.py", line 99, in load_user
    return User.query.get(int(id))
  File "c:\users\dell\appdata\local\programs\python\python38\lib\site-packages\flask_sqlalchemy\__init__.py", line 550, in __get__
    mapper = orm.class_mapper(type)
  File "c:\users\dell\appdata\local\programs\python\python38\lib\site-packages\sqlalchemy\orm\base.py", line 436, in class_mapper
    mapper = _inspect_mapped_class(class_, configure=configure)
  File "c:\users\dell\appdata\local\programs\python\python38\lib\site-packages\sqlalchemy\orm\base.py", line 415, in _inspect_mapped_class
    mapper._check_configure()
  File "c:\users\dell\appdata\local\programs\python\python38\lib\site-packages\sqlalchemy\orm\mapper.py", line 1873, in _check_configure
    _configure_registries({self.registry}, cascade=True)
  File "c:\users\dell\appdata\local\programs\python\python38\lib\site-packages\sqlalchemy\orm\mapper.py", line 3384, in _configure_registries
    _do_configure_registries(registries, cascade)
  File "c:\users\dell\appdata\local\programs\python\python38\lib\site-packages\sqlalchemy\orm\mapper.py", line 3419, in _do_configure_registries
    raise e
sqlalchemy.exc.InvalidRequestError: One or more mappers failed to initialize - can't proceed with initialization of other mappers. Triggering mapper: 'mapped class User->user'. Original exception was: Error creating backref 'user_id' on relationship 'User.CurrentStock': property of that name exists on mapper 'mapped class CurrentStock->current_stock'
2022-02-17 08:58:01,259 INFO: Microblog startup [in C:\Users\Dell\Documents\finance\app\__init__.py:78]
2022-02-17 08:58:14,844 INFO: Microblog startup [in C:\Users\Dell\Documents\finance\app\__init__.py:78]
2022-02-17 09:05:16,252 INFO: Microblog startup [in C:\Users\Dell\Documents\finance\app\__init__.py:78]
2022-02-17 09:05:32,152 INFO: Microblog startup [in C:\Users\Dell\Documents\finance\app\__init__.py:78]
2022-02-17 09:06:36,936 INFO: Microblog startup [in C:\Users\Dell\Documents\finance\app\__init__.py:78]
